Workbook

Sheet إزاي تملاه
A1: سجل المصنع اليومي
A2: الهدف: أسبوعين على الأقل من الشغل الحقيقي، عشان نبني الجدولة على أرقامكم مش على تخمين.
A4: إزاي تملاه
A5: • الخانات الصفرا بتتملي. الخانات الرمادي بتتحسب لوحدها، ما تكتبش فيها.
A6: • السطر الأخضر (رقم 3) مثال بس. سيبه زي ما هو واكتب من السطر 4.
A7: • الخانات اللي فيها سهم: اختار من القائمة.
A8: • التاريخ يتكتب كده: 2026-10-20. والساعة كده: 14:30.
A10: كل تاب بيتملي إمتى ومين
A11: • الطلبات: أول ما الطلب ييجي (حتى لو اترفض أو ما اتسلمش). ولما يتسلم، اكتب يوم التسليم والحالة.
A12: • الدفعات: المحمّص بعد كل دفعة: الوزن قبل وبعد، والساعة، ودرجة الغاز.
A13: • الأعطال والغاز: أي وقفة، وأي تغيير أنبوبة، وأي غياب.
A14: • الشكاوى: كل شكوى، ومعاها تاريخ الدفعة لو معروف.
... A21: الملف ده بتاعكم. أسماء العملاء بتفضل عندكم، وإحنا بنحتاج الأرقام بس.

Sheet الطلبات
A1: سجل الطلبات: كل طلب في سطر، حتى اللي اترفض
A2: تاريخ الطلب | B2: العميل (اسم أو كود) | C2: نوع العميل | D2: الخلطة | E2: بهيل؟ | F2: حب ولا مطحون | G2: درجة التحميص | H2: الكمية (كيلو) | I2: مطلوب يوم | J2: اتسلم يوم | K2: الحالة | L2: اتأخر كام يوم | M2: ملاحظات (ليه اتأخر أو اترفض؟)
A3: 46315 | B3: محل أ | C3: محل | D3: 190 | E3: أيوه | F3: مطحون | G3: وسط | H3: 25 | I3: 46316 | J3: 46317 | K3: اتسلم | L3: =IF(OR(I3="",J3=""),"",MAX(0,J3-I3)) -> 1 | M3: مثال: المحمصة كانت مشغولة بأوردر تحميص
A4: 46298 | B4: محل الفردوس | C4: محل | D4: 190 | E4: أيوه | F4: مطحون | G4: وسط | H4: 20 | I4: 46299 | J4: 46298 | K4: اتسلم | L4: =IF(OR(I4="",J4=""),"",MAX(0,J4-I4)) -> 0
A5: 46298 | B5: طلبات الموقع | C5: أونلاين | D5: 250 | E5: أيوه | F5: مطحون | G5: وسط | H5: 8 | I5: 46300 | J5: 46299 | K5: اتسلم | L5: =IF(OR(I5="",J5=""),"",MAX(0,J5-I5)) -> 0
A6: 46299 | B6: سوبر ماركت الهدى | C6: سوبر ماركت | D6: 190 | E6: أيوه | F6: مطحون | G6: وسط | H6: 60 | I6: 46302 | J6: 46300 | K6: اتسلم | L6: =IF(OR(I6="",J6=""),"",MAX(0,J6-I6)) -> 0
A7: 46299 | B7: محل السلام | C7: محل | D7: 190 | E7: أيوه | F7: مطحون | G7: وسط | H7: 30 | I7: 46300 | J7: 46300 | K7: اتسلم | L7: =IF(OR(I7="",J7=""),"",MAX(0,J7-I7)) -> 0
A8: 46299 | B8: محل الأمانة | C8: محل | D8: 190 | E8: أيوه | F8: مطحون | G8: وسط | H8: 20 | I8: 46300 | J8: 46300 | K8: اتسلم | L8: =IF(OR(I8="",J8=""),"",MAX(0,J8-I8)) -> 0
A9: 46299 | B9: طلبات الموقع | C9: أونلاين | D9: 250 | E9: أيوه | F9: مطحون | G9: وسط | H9: 6 | I9: 46301 | J9: 46300 | K9: اتسلم | L9: =IF(OR(I9="",J9=""),"",MAX(0,J9-I9)) -> 0
A10: 46300 | B10: كافيه سمر | C10: كافيه | D10: 300 | E10: لأ | F10: حب | G10: غامق | H10: 20 | I10: 46302 | J10: 46300 | K10: اتسلم | L10: =IF(OR(I10="",J10=""),"",MAX(0,J10-I10)) -> 0
A11: 46300 | B11: بن البركة | C11: محل | D11: 250 | E11: لأ | F11: مطحون | G11: وسط | H11: 20 | I11: 46301 | J11: 46301 | K11: اتسلم | L11: =IF(OR(I11="",J11=""),"",MAX(0,J11-I11)) -> 0
A12: 46300 | B12: عميل تصدير (الكويت) | C12: تصدير | D12: 250 | E12: أيوه | F12: مطحون | G12: وسط | H12: 100 | I12: 46310 | J12: 46303 | K12: اتسلم | L12: =IF(OR(I12="",J12=""),"",MAX(0,J12-I12)) -> 0
A13: 46300 | B13: طلبات الموقع | C13: أونلاين | D13: 300 | E13: أيوه | F13: مطحون | G13: وسط | H13: 6 | I13: 46302 | J13: 46303 | K13: اتسلم | L13: =IF(OR(I13="",J13=""),"",MAX(0,J13-I13)) -> 1 | M13: المحمصة كانت مشغولة بأوردرات قبله
A14: 46301 | B14: ماركة بن الريف | C14: تحميص لحساب الغير | D14: بن العميل | E14: لأ | F14: حب | G14: وسط | H14: 150 | I14: 46305 | J14: 46307 | K14: اتسلم | L14: =IF(OR(I14="",J14=""),"",MAX(0,J14-I14)) -> 2 | M14: قدّمنا أوردرات المحلات عليه
A15: 46301 | B15: محل السلام | C15: محل | D15: 190 | E15: أيوه | F15: مطحون | G15: وسط | H15: 20 | I15: 46302 | J15: 46302 | K15: اتسلم | L15: =IF(OR(I15="",J15=""),"",MAX(0,J15-I15)) -> 0
A16: 46301 | B16: طلبات الموقع | C16: أونلاين | D16: 300 | E16: أيوه | F16: مطحون | G16: وسط | H16: 8 | I16: 46303 | J16: 46305 | K16: اتسلم | L16: =IF(OR(I16="",J16=""),"",MAX(0,J16-I16)) -> 2 | M16: المحمصة كانت مشغولة بأوردرات قبله
A17: 46302 | B17: محل السلام | C17: محل | D17: 300 | E17: أيوه | F17: مطحون | G17: وسط | H17: 25 | I17: 46305 | J17: 46303 | K17: اتسلم | L17: =IF(OR(I17="",J17=""),"",MAX(0,J17-I17)) -> 0
A18: 46302 | B18: طلبات الموقع | C18: أونلاين | D18: 190 | E18: أيوه | F18: مطحون | G18: وسط | H18: 4 | I18: 46305 | J18: 46307 | K18: اتسلم | L18: =IF(OR(I18="",J18=""),"",MAX(0,J18-I18)) -> 2 | M18: المحمصة كانت مشغولة بأوردرات قبله
A19: 46303 | B19: محل النور | C19: محل | D19: 250 | E19: أيوه | F19: مطحون | G19: وسط | H19: 25 | I19: 46305 | J19: 46305 | K19: اتسلم | L19: =IF(OR(I19="",J19=""),"",MAX(0,J19-I19)) -> 0
A20: 46303 | B20: طلبات الموقع | C20: أونلاين | D20: 250 | E20: أيوه | F20: مطحون | G20: وسط | H20: 8 | I20: 46305 | J20: 46307 | K20: اتسلم | L20: =IF(OR(I20="",J20=""),"",MAX(0,J20-I20)) -> 2 | M20: المحمصة كانت مشغولة بأوردرات قبله
A21: 46305 | B21: بن الحرمين | C21: محل | D21: 250 | E21: أيوه | F21: مطحون | G21: وسط | H21: 25 | I21: 46307 | J21: 46306 | K21: اتسلم | L21: =IF(OR(I21="",J21=""),"",MAX(0,J21-I21)) -> 0
A22: 46305 | B22: سوبر ماركت المدينة | C22: سوبر ماركت | D22: 190 | E22: أيوه | F22: مطحون | G22: وسط | H22: 50 | I22: 46308 | J22: 46308 | K22: اتسلم | L22: =IF(OR(I22="",J22=""),"",MAX(0,J22-I22)) -> 0
A23: 46305 | B23: طلبات الموقع | C23: أونلاين | D23: 250 | E23: أيوه | F23: مطحون | G23: وسط | H23: 8 | I23: 46307 | J23: 46309 | K23: اتسلم | L23: =IF(OR(I23="",J23=""),"",MAX(0,J23-I23)) -> 2 | M23: المحمصة كانت مشغولة بأوردرات قبله
A24: 46306 | B24: ماركة بن الريف | C24: تحميص لحساب الغير | D24: بن العميل | E24: لأ | F24: حب | G24: وسط | H24: 300 | I24: 46308 | K24: اترفض | L24: =IF(OR(I24="",J24=""),"",MAX(0,J24-I24)) | M24: المحمصة مليانة الأسبوع ده، والكمية كبيرة
A25: 46306 | B25: بن البركة | C25: محل | D25: 190 | E25: أيوه | F25: مطحون | G25: وسط | H25: 25 | I25: 46308 | J25: 46309 | K25: اتسلم | L25: =IF(OR(I25="",J25=""),"",MAX(0,J25-I25)) -> 1 | M25: المحمصة كانت مشغولة بأوردرات قبله
A26: 46306 | B26: طلبات الموقع | C26: أونلاين | D26: 190 | E26: أيوه | F26: مطحون | G26: وسط | H26: 6 | I26: 46308 | J26: 46309 | K26: اتسلم | L26: =IF(OR(I26="",J26=""),"",MAX(0,J26-I26)) -> 1 | M26: المحمصة كانت مشغولة بأوردرات قبله
A27: 46307 | B27: محل السلام | C27: محل | D27: 250 | E27: أيوه | F27: مطحون | G27: وسط | H27: 25 | I27: 46309 | J27: 46310 | K27: اتسلم | L27: =IF(OR(I27="",J27=""),"",MAX(0,J27-I27)) -> 1 | M27: اتأخر بسبب عطل البكرة
A28: 46307 | B28: محل الأمانة | C28: محل | D28: 300 | E28: أيوه | F28: مطحون | G28: وسط | H28: 25 | I28: 46309 | J28: 46310 | K28: اتسلم | L28: =IF(OR(I28="",J28=""),"",MAX(0,J28-I28)) -> 1 | M28: اتأخر بسبب عطل البكرة
A29: 46307 | B29: سوبر ماركت الهدى | C29: سوبر ماركت | D29: 190 | E29: أيوه | F29: مطحون | G29: وسط | H29: 60 | I29: 46310 | K29: لسه | L29: =IF(OR(I29="",J29=""),"",MAX(0,J29-I29))
A30: 46307 | B30: طلبات الموقع | C30: أونلاين | D30: 300 | E30: أيوه | F30: مطحون | G30: وسط | H30: 6 | I30: 46309 | J30: 46310 | K30: اتسلم | L30: =IF(OR(I30="",J30=""),"",MAX(0,J30-I30)) -> 1 | M30: اتأخر بسبب عطل البكرة
A31: 46308 | B31: كافيه سمر | C31: كافيه | D31: 250 | E31: لأ | F31: حب | G31: غامق | H31: 20 | I31: 46310 | K31: لسه | L31: =IF(OR(I31="",J31=""),"",MAX(0,J31-I31))
A32: 46308 | B32: ماركة قهوة زمان | C32: تحميص لحساب الغير | D32: بن العميل | E32: لأ | F32: حب | G32: غامق | H32: 100 | I32: 46312 | K32: لسه | L32: =IF(OR(I32="",J32=""),"",MAX(0,J32-I32))
A33: 46308 | B33: محل الفردوس | C33: محل | D33: سعودي | E33: أيوه | F33: مطحون | G33: أشقر | H33: 25 | I33: 46309 | J33: 46310 | K33: اتسلم | L33: =IF(OR(I33="",J33=""),"",MAX(0,J33-I33)) -> 1 | M33: اتأخر بسبب عطل البكرة
A34: 46308 | B34: طلبات الموقع | C34: أونلاين | D34: 250 | E34: أيوه | F34: مطحون | G34: وسط | H34: 6 | I34: 46310 | K34: لسه | L34: =IF(OR(I34="",J34=""),"",MAX(0,J34-I34))
A35: 46309 | B35: محل الأمانة | C35: محل | D35: 190 | E35: أيوه | F35: مطحون | G35: وسط | H35: 25 | I35: 46310 | K35: لسه | L35: =IF(OR(I35="",J35=""),"",MAX(0,J35-I35))
A36: 46309 | B36: طلبات الموقع | C36: أونلاين | D36: 190 | E36: أيوه | F36: مطحون | G36: وسط | H36: 6 | I36: 46312 | K36: لسه | L36: =IF(OR(I36="",J36=""),"",MAX(0,J36-I36))
A37: 46310 | B37: بن البركة | C37: محل | D37: 190 | E37: أيوه | F37: مطحون | G37: وسط | H37: 25 | I37: 46312 | K37: لسه | L37: =IF(OR(I37="",J37=""),"",MAX(0,J37-I37))
A38: 46310 | B38: طلبات الموقع | C38: أونلاين | D38: 190 | E38: أيوه | F38: مطحون | G38: وسط | H38: 5 | I38: 46312 | K38: لسه | L38: =IF(OR(I38="",J38=""),"",MAX(0,J38-I38))
L39: =IF(OR(I39="",J39=""),"",MAX(0,J39-I39))
L40: =IF(OR(I40="",J40=""),"",MAX(0,J40-I40))
...

Sheet الدفعات
A1: سجل الدفعات: كل دفعة تحميص في سطر
A2: التاريخ | B2: بدأت الساعة | C2: خلصت الساعة | D2: المحمصة | E2: نوع البن | F2: درجة التحميص | G2: الوزن قبل (أخضر، كيلو) | H2: الوزن بعد (محمّص، كيلو) | I2: الفاقد | J2: المدة (دقيقة) | K2: الغاز (الدرجة أو الضغط) | L2: المحمّص | M2: لـ | N2: ملاحظات (اللون، الطعم، أي مشكلة)
A3: 46315 | B3: 0.375 | C3: 0.47916667 | D3: 1 | E3: برازيلي | F3: وسط | G3: 14 | H3: 12.6 | I3: =IF(OR(G3="",H3=""),"",1-H3/G3) -> 0.1 | J3: =IF(OR(B3="",C3=""),"",ROUND(MOD(C3-B3,1)*1440,0)) -> 150 | K3: 3 | L3: أحمد | M3: أوردر | N3: مثال: اللون أغمق شوية من العادي
A4: 46298 | B4: 0.36388889 | C4: 0.43611111 | D4: 1 | E4: روبستا | F4: وسط | G4: 8 | H4: 7.3 | I4: =IF(OR(G4="",H4=""),"",1-H4/G4) -> 0.0875 | J4: =IF(OR(B4="",C4=""),"",ROUND(MOD(C4-B4,1)*1440,0)) -> 104 | K4: 4 | L4: أحمد | M4: أوردر
A5: 46298 | B5: 0.44166667 | C5: 0.54097222 | D5: 1 | E5: برازيلي | F5: وسط | G5: 13.3 | H5: 11.9 | I5: =IF(OR(G5="",H5=""),"",1-H5/G5) -> 0.10526316 | J5: =IF(OR(B5="",C5=""),"",ROUND(MOD(C5-B5,1)*1440,0)) -> 143 | K5: 3 | L5: أحمد | M5: أوردر
A6: 46298 | B6: 0.54791667 | C6: 0.62430556 | D6: 1 | E6: روبستا | F6: وسط | G6: 8 | H6: 7.2 | I6: =IF(OR(G6="",H6=""),"",1-H6/G6) -> 0.1 | J6: =IF(OR(B6="",C6=""),"",ROUND(MOD(C6-B6,1)*1440,0)) -> 110 | K6: 3 | L6: أحمد | M6: أوردر
A7: 46298 | B7: 0.63472222 | C7: 0.71666667 | D7: 1 | E7: برازيلي | F7: وسط | G7: 8 | H7: 7.2 | I7: =IF(OR(G7="",H7=""),"",1-H7/G7) -> 0.1 | J7: =IF(OR(B7="",C7=""),"",ROUND(MOD(C7-B7,1)*1440,0)) -> 118 | K7: 3.5 | L7: أحمد | M7: أوردر
A8: 46298 | B8: 0.725 | C8: 0.80625 | D8: 1 | E8: كولومبي | F8: وسط | G8: 8 | H8: 7.2 | I8: =IF(OR(G8="",H8=""),"",1-H8/G8) -> 0.1 | J8: =IF(OR(B8="",C8=""),"",ROUND(MOD(C8-B8,1)*1440,0)) -> 117 | K8: 3 | L8: محمود | M8: أوردر
A9: 46298 | B9: 0.81597222 | C9: 0.89097222 | D9: 1 | E9: هندي | F9: وسط | G9: 8 | H9: 7.2 | I9: =IF(OR(G9="",H9=""),"",1-H9/G9) -> 0.1 | J9: =IF(OR(B9="",C9=""),"",ROUND(MOD(C9-B9,1)*1440,0)) -> 108 | K9: 3 | L9: محمود | M9: أوردر
A10: 46298 | B10: 0.89791667 | C10: 0.0069444444 | D10: 1 | E10: برازيلي | F10: وسط | G10: 14 | H10: 12.6 | I10: =IF(OR(G10="",H10=""),"",1-H10/G10) -> 0.1 | J10: =IF(OR(B10="",C10=""),"",ROUND(MOD(C10-B10,1)*1440,0)) -> 157 | K10: 3 | L10: محمود | M10: مخزن
A11: 46299 | B11: 0.35763889 | C11: 0.46458333 | D11: 1 | E11: روبستا | F11: وسط | G11: 14 | H11: 12.5 | I11: =IF(OR(G11="",H11=""),"",1-H11/G11) -> 0.10714286 | J11: =IF(OR(B11="",C11=""),"",ROUND(MOD(C11-B11,1)*1440,0)) -> 154 | K11: 3 | L11: أحمد | M11: أوردر
A12: 46299 | B12: 0.46805556 | C12: 0.56597222 | D12: 1 | E12: برازيلي | F12: وسط | G12: 14 | H12: 12.6 | I12: =IF(OR(G12="",H12=""),"",1-H12/G12) -> 0.1 | J12: =IF(OR(B12="",C12=""),"",ROUND(MOD(C12-B12,1)*1440,0)) -> 141 | K12: 3 | L12: أحمد | M12: أوردر
A13: 46299 | B13: 0.57083333 | C13: 0.64930556 | D13: 1 | E13: برازيلي | F13: وسط | G13: 8 | H13: 7.3 | I13: =IF(OR(G13="",H13=""),"",1-H13/G13) -> 0.0875 | J13: =IF(OR(B13="",C13=""),"",ROUND(MOD(C13-B13,1)*1440,0)) -> 113 | K13: 3 | L13: أحمد | M13: أوردر
A14: 46299 | B14: 0.65694444 | C14: 0.74305556 | D14: 1 | E14: روبستا | F14: وسط | G14: 10.7 | H14: 9.6 | I14: =IF(OR(G14="",H14=""),"",1-H14/G14) -> 0.10280374 | J14: =IF(OR(B14="",C14=""),"",ROUND(MOD(C14-B14,1)*1440,0)) -> 124 | K14: 4 | L14: أحمد | M14: أوردر
A15: 46299 | B15: 0.74930556 | C15: 0.85208333 | D15: 1 | E15: برازيلي | F15: وسط | G15: 14 | H15: 12.5 | I15: =IF(OR(G15="",H15=""),"",1-H15/G15) -> 0.10714286 | J15: =IF(OR(B15="",C15=""),"",ROUND(MOD(C15-B15,1)*1440,0)) -> 148 | K15: 4 | L15: محمود | M15: أوردر
... A22: 46300 | B22: 0.71875 | C22: 0.79930556 | D22: 1 | E22: روبستا | F22: وسط | G22: 8 | H22: 7.2 | I22: =IF(OR(G22="",H22=""),"",1-H22/G22) -> 0.1 | J22: =IF(OR(B22="",C22=""),"",ROUND(MOD(C22-B22,1)*1440,0)) -> 116 | K22: 3.5 | L22: محمود | M22: أوردر
A23: 46300 | B23: 0.80972222 | C23: 0.88958333 | D23: 1 | E23: برازيلي | F23: وسط | G23: 8.7 | H23: 7.6 | I23: =IF(OR(G23="",H23=""),"",1-H23/G23) -> 0.12643678 | J23: =IF(OR(B23="",C23=""),"",ROUND(MOD(C23-B23,1)*1440,0)) -> 115 | K23: 3.5 | L23: محمود | M23: أوردر | N23: اللون أغمق من العادي
A24: 46300 | B24: 0.89583333 | C24: 0.97152778 | D24: 1 | E24: كولومبي | F24: وسط | G24: 8 | H24: 7.1 | I24: =IF(OR(G24="",H24=""),"",1-H24/G24) -> 0.1125 | J24: =IF(OR(B24="",C24=""),"",ROUND(MOD(C24-B24,1)*1440,0)) -> 109 | K24: 3.5 | L24: محمود | M24: أوردر
A25: 46301 | B25: 0.36180556 | C25: 0.46736111 | D25: 1 | E25: روبستا | F25: وسط | G25: 14 | H25: 12.6 | I25: =IF(OR(G25="",H25=""),"",1-H25/G25) -> 0.1 | J25: =IF(OR(B25="",C25=""),"",ROUND(MOD(C25-B25,1)*1440,0)) -> 152 | K25: 3.5 | L25: أحمد | M25: أوردر
A26: 46301 | B26: 0.47152778 | C26: 0.54861111 | D26: 1 | E26: روبستا | F26: وسط | G26: 8 | H26: 7.1 | I26: =IF(OR(G26="",H26=""),"",1-H26/G26) -> 0.1125 | J26: =IF(OR(B26="",C26=""),"",ROUND(MOD(C26-B26,1)*1440,0)) -> 111 | K26: 3.5 | L26: أحمد | M26: أوردر
A27: 46301 | B27: 0.55555556 | C27: 0.6625 | D27: 1 | E27: برازيلي | F27: وسط | G27: 14 | H27: 12.6 | I27: =IF(OR(G27="",H27=""),"",1-H27/G27) -> 0.1 | J27: =IF(OR(B27="",C27=""),"",ROUND(MOD(C27-B27,1)*1440,0)) -> 154 | K27: 3 | L27: أحمد | M27: أوردر
A28: 46301 | B28: 0.67708333 | C28: 0.77569444 | D28: 1 | E28: برازيلي | F28: وسط | G28: 14 | H28: 12.6 | I28: =IF(OR(G28="",H28=""),"",1-H28/G28) -> 0.1 | J28: =IF(OR(B28="",C28=""),"",ROUND(MOD(C28-B28,1)*1440,0)) -> 142 | K28: 3 | L28: أحمد | M28: أوردر
A29: 46301 | B29: 0.78611111 | C29: 0.89305556 | D29: 1 | E29: برازيلي | F29: وسط | G29: 14 | H29: 12.7 | I29: =IF(OR(G29="",H29=""),"",1-H29/G29) -> 0.092857143 | J29: =IF(OR(B29="",C29=""),"",ROUND(MOD(C29-B29,1)*1440,0)) -> 154 | K29: 3.5 | L29: محمود | M29: أوردر
A30: 46301 | B30: 0.9 | C30: 0.98055556 | D30: 1 | E30: برازيلي | F30: وسط | G30: 8 | H30: 7.1 | I30: =IF(OR(G30="",H30=""),"",1-H30/G30) -> 0.1125 | J30: =IF(OR(B30="",C30=""),"",ROUND(MOD(C30-B30,1)*1440,0)) -> 116 | K30: 3.5 | L30: محمود | M30: أوردر
A31: 46302 | B31: 0.35833333 | C31: 0.43402778 | D31: 1 | E31: روبستا | F31: وسط | G31: 8 | H31: 7.3 | I31: =IF(OR(G31="",H31=""),"",1-H31/G31) -> 0.0875 | J31: =IF(OR(B31="",C31=""),"",ROUND(MOD(C31-B31,1)*1440,0)) -> 109 | K31: 4 | L31: أحمد | M31: أوردر
A32: 46302 | B32: 0.44305556 | C32: 0.51666667 | D32: 1 | E32: برازيلي | F32: وسط | G32: 8 | H32: 7.1 | I32: =IF(OR(G32="",H32=""),"",1-H32/G32) -> 0.1125 | J32: =IF(OR(B32="",C32=""),"",ROUND(MOD(C32-B32,1)*1440,0)) -> 106 | K32: 3 | L32: أحمد | M32: أوردر
A33: 46302 | B33: 0.52083333 | C33: 0.59236111 | D33: 1 | E33: روبستا | F33: وسط | G33: 8 | H33: 7.2 | I33: =IF(OR(G33="",H33=""),"",1-H33/G33) -> 0.1 | J33: =IF(OR(B33="",C33=""),"",ROUND(MOD(C33-B33,1)*1440,0)) -> 103 | K33: 3 | L33: أحمد | M33: أوردر
A34: 46302 | B34: 0.59930556 | C34: 0.69097222 | D34: 1 | E34: برازيلي | F34: وسط | G34: 10.9 | H34: 9.8 | I34: =IF(OR(G34="",H34=""),"",1-H34/G34) -> 0.10091743 | J34: =IF(OR(B34="",C34=""),"",ROUND(MOD(C34-B34,1)*1440,0)) -> 132 | K34: 3.5 | L34: أحمد | M34: أوردر
A35: 46302 | B35: 0.69791667 | C35: 0.78125 | D35: 1 | E35: كولومبي | F35: وسط | G35: 8 | H35: 7.2 | I35: =IF(OR(G35="",H35=""),"",1-H35/G35) -> 0.1 | J35: =IF(OR(B35="",C35=""),"",ROUND(MOD(C35-B35,1)*1440,0)) -> 120 | K35: 4 | L35: أحمد | M35: أوردر
... A56: 46306 | B56: 0.81458333 | C56: 0.91944444 | D56: 1 | E56: بن العميل | F56: وسط | G56: 14 | H56: 12.6 | I56: =IF(OR(G56="",H56=""),"",1-H56/G56) -> 0.1 | J56: =IF(OR(B56="",C56=""),"",ROUND(MOD(C56-B56,1)*1440,0)) -> 151 | K56: 3 | L56: محمود | M56: أوردر
A57: 46306 | B57: 0.92777778 | C57: 0.022222222 | D57: 1 | E57: بن العميل | F57: وسط | G57: 10 | H57: 8.6 | I57: =IF(OR(G57="",H57=""),"",1-H57/G57) -> 0.14 | J57: =IF(OR(B57="",C57=""),"",ROUND(MOD(C57-B57,1)*1440,0)) -> 136 | K57: 3 | L57: محمود | M57: أوردر | N57: اللون أغمق من العادي
A58: 46307 | B58: 0.36458333 | C58: 0.4375 | D58: 1 | E58: روبستا | F58: وسط | G58: 8 | H58: 7.2 | I58: =IF(OR(G58="",H58=""),"",1-H58/G58) -> 0.1 | J58: =IF(OR(B58="",C58=""),"",ROUND(MOD(C58-B58,1)*1440,0)) -> 105 | K58: 4 | L58: أحمد | M58: أوردر
A59: 46307 | B59: 0.44652778 | C59: 0.52569444 | D59: 1 | E59: برازيلي | F59: وسط | G59: 8 | H59: 7.2 | I59: =IF(OR(G59="",H59=""),"",1-H59/G59) -> 0.1 | J59: =IF(OR(B59="",C59=""),"",ROUND(MOD(C59-B59,1)*1440,0)) -> 114 | K59: 3.5 | L59: أحمد | M59: أوردر
A60: 46307 | B60: 0.53541667 | C60: 0.61111111 | D60: 1 | E60: كولومبي | F60: وسط | G60: 8 | H60: 7.2 | I60: =IF(OR(G60="",H60=""),"",1-H60/G60) -> 0.1 | J60: =IF(OR(B60="",C60=""),"",ROUND(MOD(C60-B60,1)*1440,0)) -> 109 | K60: 3 | L60: أحمد | M60: أوردر
A61: 46307 | B61: 0.61944444 | C61: 0.69722222 | D61: 1 | E61: هندي | F61: وسط | G61: 8 | H61: 7.2 | I61: =IF(OR(G61="",H61=""),"",1-H61/G61) -> 0.1 | J61: =IF(OR(B61="",C61=""),"",ROUND(MOD(C61-B61,1)*1440,0)) -> 112 | K61: 3.5 | L61: أحمد | M61: أوردر
A62: 46307 | B62: 0.70416667 | C62: 0.80833333 | D62: 1 | E62: برازيلي | F62: وسط | G62: 14 | H62: 12.7 | I62: =IF(OR(G62="",H62=""),"",1-H62/G62) -> 0.092857143 | J62: =IF(OR(B62="",C62=""),"",ROUND(MOD(C62-B62,1)*1440,0)) -> 150 | K62: 3.5 | L62: أحمد | M62: أوردر
A63: 46307 | B63: 0.81875 | C63: 0.89166667 | D63: 1 | E63: برازيلي | F63: وسط | G63: 8 | H63: 7.1 | I63: =IF(OR(G63="",H63=""),"",1-H63/G63) -> 0.1125 | J63: =IF(OR(B63="",C63=""),"",ROUND(MOD(C63-B63,1)*1440,0)) -> 105 | K63: 3 | L63: محمود | M63: أوردر
A64: 46307 | B64: 0.89861111 | C64: 0.97777778 | D64: 1 | E64: روبستا | F64: وسط | G64: 8 | H64: 7.1 | I64: =IF(OR(G64="",H64=""),"",1-H64/G64) -> 0.1125 | J64: =IF(OR(B64="",C64=""),"",ROUND(MOD(C64-B64,1)*1440,0)) -> 114 | K64: 4 | L64: محمود | M64: أوردر
A65: 46309 | B65: 0.36458333 | C65: 0.46458333 | D65: 1 | E65: برازيلي | F65: وسط | G65: 12.2 | H65: 11 | I65: =IF(OR(G65="",H65=""),"",1-H65/G65) -> 0.098360656 | J65: =IF(OR(B65="",C65=""),"",ROUND(MOD(C65-B65,1)*1440,0)) -> 144 | K65: 3 | L65: أحمد | M65: أوردر
A66: 46309 | B66: 0.47152778 | C66: 0.54444444 | D66: 1 | E66: برازيلي | F66: وسط | G66: 8 | H66: 7.2 | I66: =IF(OR(G66="",H66=""),"",1-H66/G66) -> 0.1 | J66: =IF(OR(B66="",C66=""),"",ROUND(MOD(C66-B66,1)*1440,0)) -> 105 | K66: 3.5 | L66: أحمد | M66: أوردر
...

Sheet الأعطال والغاز
A1: الأعطال وتغيير الغاز وأي وقفة
A2: التاريخ | B2: الساعة | C2: إيه اللي حصل | D2: الماكينة | E2: وقف قد إيه (ساعات) | F2: الدفعة باظت؟ | G2: ملاحظات
A3: 46316 | B3: 0.58333333 | C3: تغيير أنبوبة غاز | D3: المحمصة | E3: 0.2 | F3: لأ | G3: مثال: ركّبنا الاحتياطي وطلبنا جديدة
A4: 46301 | B4: 0.67013889 | C4: تغيير أنبوبة غاز | D4: المحمصة | E4: 0.2 | F4: لأ | G4: ركّبنا الاحتياطي وطلبنا جديدة
A5: 46305 | B5: 0.88888889 | C5: تغيير أنبوبة غاز | D5: المحمصة | E5: 0.2 | F5: لأ | G5: ركّبنا الاحتياطي وطلبنا جديدة
A6: 46308 | B6: 0.38194444 | C6: عطل | D6: المحمصة | E6: 24 | F6: أيوه | G6: بكرة البرميل اتكسرت، استنينا القطعة من القاهرة
A7: 46310 | B7: 0.55 | C7: تغيير أنبوبة غاز | D7: المحمصة | E7: 0.2 | F7: لأ | G7: ركّبنا الاحتياطي وطلبنا جديدة

Sheet الشكاوى
A1: الشكاوى: كل شكوى مع تاريخ الدفعة
A2: التاريخ | B2: العميل | C2: الخلطة | D2: تاريخ تحميص الدفعة (لو معروف) | E2: الشكوى | F2: العميل بيخزّن إزاي وقد إيه | G2: ملاحظات
A3: 46320 | B3: كافيه ب | C3: 250 | D3: 46315 | E3: مُر | F3: في علبة مفتوحة، أسبوعين | G3: مثال
A4: 46303 | B4: بن الحرمين | C4: 300 | E4: الهيل كتير | G4: قال الطعم مختلف عن الشهر اللي فات
A5: 46305 | B5: كافيه سمر | C5: 190 | D5: 46300 | E5: مُر | F5: كيس مفتوح، 10 أيام | G5: اللون كان غامق
A6: 46310 | B6: كافيه ركن القهوة | C6: 250 | D6: 46302 | E6: خفيف | F6: كيس مفتوح، 3 أسابيع | G6: التخزين طويل
A7: 46311 | B7: محل الأمانة | C7: 250 | D7: 46306 | E7: مُر | F7: كيس مفتوح، 10 أيام | G7: اللون كان غامق

Sheet الملخص
A1: ملخص تلقائي (من غير سطر المثال)
A3: الطلبات
A4: عدد الطلبات | B4: =COUNT(الطلبات!H4:H503) -> 35
A5: إجمالي الكيلوهات المطلوبة | B5: =SUM(الطلبات!H4:H503) -> 1272
A6: كيلوهات اترفضت | B6: =SUMIFS(الطلبات!H4:H503,الطلبات!K4:K503,"اترفض") -> 300
A7: طلبات اتأخرت (يوم أو أكتر) | B7: =COUNTIF(الطلبات!L4:L503,">0") -> 12
A8: نسبة الطلبات المتأخرة (من اللي اتسلمت) | B8: =IFERROR(B7/COUNT(الطلبات!L4:L503),"-") -> 0.46153846
A9: متوسط التأخير للمتأخر (يوم) | B9: =IFERROR(AVERAGEIF(الطلبات!L4:L503,">0"),"-") -> 1.4166667
A10: كيلوهات تحميص لحساب الغير | B10: =SUMIFS(الطلبات!H4:H503,الطلبات!C4:C503,"تحميص لحساب الغير") -> 550
A11: الدفعات
A12: عدد الدفعات | B12: =COUNT(الدفعات!G4:G503) -> 75
A13: كيلو أخضر اتحمّص | B13: =SUM(الدفعات!G4:G503) -> 779
A14: متوسط وزن الدفعة (كيلو) | B14: =IFERROR(AVERAGE(الدفعات!G4:G503),"-") -> 10.386667
A15: متوسط الفاقد: أشقر | B15: =IFERROR(AVERAGEIFS(الدفعات!I4:I503,الدفعات!F4:F503,"أشقر"),"-") -> 0.063392857
A16: متوسط الفاقد: وسط | B16: =IFERROR(AVERAGEIFS(الدفعات!I4:I503,الدفعات!F4:F503,"وسط"),"-") -> 0.10131942
A17: متوسط الفاقد: غامق | B17: =IFERROR(AVERAGEIFS(الدفعات!I4:I503,الدفعات!F4:F503,"غامق"),"-") -> 0.15
A18: متوسط مدة الدفعة (دقيقة) | B18: =IFERROR(AVERAGE(الدفعات!J4:J503),"-") -> 126.70667
A19: الوقفات والشكاوى
A20: ساعات وقوف من الأعطال | B20: =SUMIFS('الأعطال والغاز'!E4:E503,'الأعطال والغاز'!C4:C503,"عطل") -> 24
A21: عدد مرات تغيير الغاز | B21: =COUNTIF('الأعطال والغاز'!C4:C503,"تغيير أنبوبة غاز") -> 3
A22: عدد الشكاوى | B22: =COUNTA(الشكاوى!A4:A503) -> 4

Sheet القوائم
A1: cust_type | B1: blend | C1: yesno | D1: form | E1: roast | F1: status | G1: origin | H1: dest | I1: event | J1: machine | K1: complaint
A2: محل | B2: 190 | C2: أيوه | D2: مطحون | E2: أشقر | F2: اتسلم | G2: روبستا | H2: أوردر | I2: عطل | J2: المحمصة | K2: مُر
A3: سوبر ماركت | B3: 250 | C3: لأ | D3: حب | E3: وسط | F3: اتسلم ناقص | G3: برازيلي | H3: مخزن | I3: تغيير أنبوبة غاز | J3: المطحنة | K3: خفيف
A4: كافيه | B4: 300 | E4: غامق | F4: اتأجل | G4: كولومبي | I4: الغاز خلص | J4: التغليف | K4: محروق
A5: أونلاين | B5: سعودي | F5: اترفض | G5: هندي | I5: انقطاع كهرباء | J5: الشفاط/التبريد | K5: حامض
A6: تصدير | B6: بن العميل | F6: لسه | G6: سعودي | I6: غياب عامل | J6: تاني | K6: مختلف عن المرة اللي فاتت
A7: تحميص لحساب الغير | G7: بن العميل | I7: تنظيف المطحنة | K7: الهيل قليل
I8: تاني | K8: الهيل كتير
K9: تاني
